#VRML_SIM R2023a utf8
PROTO FourWheelsRobot [
  field SFVec3f    translation  0 0 0
  field SFRotation rotation     0 0 1 0
  field SFFloat    bodyMass     1
]
{
  Robot {
  translation IS translation
  rotation IS rotation
  children [
    DEF ROBOT_BODY Shape {
      appearance PBRAppearance {
        baseColor 1 0 0
        roughness 0.5
        metalness 0
      }
      geometry Box {
        size 0.2 0.1 0.05
      }
    }
    HingeJoint {
      jointParameters HingeJointParameters {
        axis 0 1 0
        anchor 0.05 0.06 0
      }
      device [
        RotationalMotor {
          name "wheel1"
        }
      ]
      endPoint DEF WHEEL1 Solid {
        translation 0.05 0.06 0
        rotation 1 -3.925223937639758e-17 -9.813059844099396e-17 1.5707999999999998
        children [
          DEF WHEEL_SHAPE Shape {
            appearance PBRAppearance {
              baseColor 0 1 0
              roughness 0.5
              metalness 0
            }
            geometry Cylinder {
              height 0.02
              radius 0.04
            }
          }
        ]
        boundingObject USE WHEEL_SHAPE
        physics Physics {
        }
      }
    }
    HingeJoint {
      jointParameters HingeJointParameters {
        axis 0 1 0
        anchor 0.05 -0.06 0
      }
      device [
        RotationalMotor {
          name "wheel2"
        }
      ]
      endPoint DEF WHEEL2 Solid {
        translation 0.05 -0.06 0
        rotation 1 -3.925223937639758e-17 -9.813059844099396e-17 1.5707999999999998
        children [
          USE WHEEL_SHAPE
        ]
        name "solid(1)"
        boundingObject USE WHEEL_SHAPE
        physics Physics {
        }
      }
    }
    HingeJoint {
      jointParameters HingeJointParameters {
        axis 0 1 0
        anchor -0.05 0.06 0
      }
      device [
        RotationalMotor {
          name "wheel3"
        }
      ]
      endPoint DEF WHEEL3 Solid {
        translation -0.05 0.06 0
        rotation 1 1.3738283781739159e-16 -5.887835906459639e-17 1.5707999999999989
        children [
          USE WHEEL_SHAPE
        ]
        name "solid(2)"
        boundingObject USE WHEEL_SHAPE
        physics Physics {
        }
      }
    }
    HingeJoint {
      jointParameters HingeJointParameters {
        axis 0 1 0
        anchor -0.05 -0.06 0
      }
      device [
        RotationalMotor {
          name "wheel4"
        }
      ]
      endPoint DEF WHEEL4 Solid {
        translation -0.05 -0.06 0
        rotation 1 1.3738283781739159e-16 -5.887835906459639e-17 1.5707999999999989
        children [
          USE WHEEL_SHAPE
        ]
        name "solid(3)"
        boundingObject USE WHEEL_SHAPE
        physics Physics {
        }
      }
    }
    DistanceSensor {
      translation 0.1 0.025 0
      rotation 0 0 1 0.3
      children [
        Solid {
          children [
            DEF D_SENSOR Shape {
              appearance PBRAppearance {
                baseColor 0 0 1
                roughness 0.5
                metalness 0
              }
              geometry Box {
                size 0.01 0.01 0.01
              }
            }
          ]
          boundingObject USE D_SENSOR
        }
      ]
      name "ds_left"
    }
    DistanceSensor {
      translation 0.1 -0.025 0
      rotation 0 0 1 -0.3
      children [
        Solid {
          children [
            DEF D_SENSOR Shape {
              appearance PBRAppearance {
                baseColor 0 0 1
                roughness 0.5
                metalness 0
              }
              geometry Box {
                size 0.01 0.01 0.01
              }
            }
          ]
          boundingObject USE D_SENSOR
        }
      ]
      name "ds_right"
    }
  ]
  name "robot1"
  boundingObject USE ROBOT_BODY
  physics Physics {
    density -1
    bodyMass IS bodyMass
  }
  controller "four_wheeled_collision_avoidance"
}
}